<?xml version="1.0"?>
<robot xmlns:xacro="http://www.ros.org/wiki/xacro" name="barista_bot">

  <!-- macro for wheel -->
  <xacro:macro name="wheel" params="wheel_name ref_frame:=chassis side">
  <!-- params:  
    "wheel_name" is the name of the link
    "ref_frame" reference frame for the joint
    "side" 1 for left wheel, -1 for right wheel -->

    <joint name="${wheel_name}_joint" type="continuous">
      <origin xyz="0 ${side * 0.25} -0.0775" rpy="0 0 0"/>
      <parent link="${ref_frame}"/>
      <child link="${wheel_name}"/>
      <axis xyz="0 1 0" />
      <limit effort="1000.0" velocity="100.0" />
      <dynamics damping="0.0" friction="0.1"/>
    </joint>

    <link name="${wheel_name}">
      <visual>
        <origin xyz="0 0 0" rpy="0 1.5707 1.5707"/>
        <geometry>
          <cylinder length="0.0206" radius="0.0352"/>
        </geometry>
        <material name="black"/>
      </visual>

      <collision>
        <origin xyz="0 0 0" rpy="0 1.5707 1.5707"/>
        <geometry>
          <cylinder length="0.0206" radius="0.0352"/>
        </geometry>
      </collision>

      <inertial>
        <mass value="0.5"/>
        <origin xyz="0 0 0" rpy="0 1.5707 1.5707"/>
        <inertia ixx="0.00017256166666666667" ixy="0" ixz="0" iyy="0.00017256166666666667" iyz="0" izz="0.00030976"/>
      </inertial>
    </link>

    <gazebo reference="${wheel_name}">
      <kp>1000000000000000000000000000.0</kp>
      <kd>1000000000000000000000000000.0</kd>
      <mu1>10.0</mu1>
      <mu2>10.0</mu2>
      <material>Gazebo/Black</material>
    </gazebo>
  </xacro:macro>
</robot>
